Workbook

Sheet Fuse Database
A1: Fuse Database
A2: 115 parts · cleaned & consolidated from fuses.csv · sorted by current rating, then AC voltage
A4: Mfr Part # | B4: Manufacturer | C4: Series | D4: Description | E4: Fuse Type | F4: Mounting Type | G4: Response Time | H4: Current Rating (A) | I4: Voltage AC (V) | J4: Voltage DC (V) | K4: Breaking Cap. AC (A) | L4: Breaking Cap. DC (A) | M4: Breaking Capacity (raw) | N4: Melting I²t (A²s) | O4: Approval Agency | P4: Operating Temperature | Q4: Package / Case | R4: Size / Dimension | S4: Color | T4: Datasheet | U4: Source File | V4: QC Flag
A5: 0208005.MXEP | B5: Littelfuse Inc. | C5: 208 | D5: FUSE GLASS 5A 350VAC 2AG | E5: Cartridge, Glass | F5: Through Hole | G5: Fast Blow | H5: 5 | I5: 350 | K5: 100 | L5: 100 | M5: 100A | N5: 17 | O5: CE, cURus, PSE | P5: -55°C ~ 125°C | Q5: 2AG, 5mm x 15mm (Axial) | R5: 0.185" Dia x 0.570" L (4.70mm x 14.48mm) | S5: — | T5: Link | U5: fuses.csv | V5: OK
A6: SMG-V5 | B6: Mersen USA Newburyport-MA L.L.C. | C6: SMG | D6: 350V 5A .217X.59 2AG FA-L | E6: Cartridge, Glass | F6: Through Hole | G6: Fast Blow | H6: 5 | I6: 350 | K6: 100 | L6: 100 | M6: 100A | O6: CSA, UR | P6: — | Q6: 2AG, 5mm x 15mm (Axial) | R6: 0.244" Dia x 0.709" L (6.20mm x 18.00mm) | S6: — | T6: Link | U6: fuses.csv | V6: OK
A7: 0514005.MXEP | B7: Littelfuse Inc. | C7: 514 | D7: FUSE CERAMIC 5A 500VAC 3AB 3AG | E7: Cartridge, Ceramic | F7: Through Hole | G7: Fast Blow | H7: 5 | I7: 500 | K7: 5000 | L7: 5000 | M7: 5kA | N7: 6.14 | O7: CE, cURus | P7: -55°C ~ 125°C | Q7: 3AB, 3AG, 1/4" x 1-1/4" (Axial) | R7: 0.275" Dia x 1.288" L (6.99mm x 32.72mm) | S7: — | T7: Link | U7: fuses.csv | V7: OK
A8: 8020.5075.PT | B8: SCHURTER Inc. | C8: SHF 6.3x32 | D8: FUSE CERAMIC 5A 500VAC 3AB 3AG | E8: Cartridge, Ceramic | F8: Through Hole | G8: Fast Blow | H8: 5 | I8: 500 | K8: 1500 | L8: 1500 | M8: 1.5kA | N8: 33.2 | O8: cURus | P8: -40°C ~ 85°C | Q8: 3AB, 3AG, 1/4" x 1-1/4" (Axial) | R8: 0.270" Dia x 1.291" L (6.85mm x 32.80mm) | S8: — | T8: Link | U8: fuses.csv | V8: OK
A9: 0479005.MXEP | B9: Littelfuse Inc. | C9: 479 | D9: FUSE GLASS 5A 600VAC 2AG | E9: Cartridge, Glass | F9: Through Hole | G9: Fast Blow | H9: 5 | I9: 600 | K9: 20 | L9: 20 | M9: 20A | O9: CE, UL | P9: — | Q9: 2AG, 5mm x 15mm (Axial) | R9: 0.184" Dia x 0.586" L (4.67mm x 14.88mm) | S9: — | T9: Link | U9: fuses.csv | V9: OK
A10: 0ADAP5000-RE | B10: Bel Fuse Inc. | C10: 0ADAP | D10: FUSE CERM 5A 600VAC 600VDC 3AB | E10: Cartridge, Ceramic | F10: Through Hole | G10: Fast Blow | H10: 5 | I10: 600 | J10: 600 | K10: 10000 | L10: 10000 | M10: 10kA | N10: 26.5 | O10: cURus | P10: -55°C ~ 125°C | Q10: 3AB, 3AG, 1/4" x 1-1/4" (Axial) | R10: 0.266" Dia x 1.292" H (6.76mm x 32.82mm) | S10: — | T10: Link | U10: fuses.csv | V10: OK
A11: AHC-V-5-R | B11: Eaton - Electronics Division | C11: AHC | D11: FUSE CERAMIC 5A 600VAC 3AB 3AG | E11: Cartridge, Ceramic | F11: Through Hole | G11: Fast Blow | H11: 5 | I11: 600 | K11: 10000 | L11: 10000 | M11: 10kA | N11: 10 | O11: UL | P11: -55°C ~ 125°C | Q11: 3AB, 3AG, 1/4" x 1-1/4" (Axial) | R11: 0.275" Dia x 1.288" L (6.99mm x 32.72mm) | S11: — | T11: Link | U11: fuses.csv | V11: OK
A12: BK-AHC-V-5-R | B12: Eaton - Electronics Division | C12: AHC | D12: FUSE CERAMIC 5A 600VAC 3AB 3AG | E12: Cartridge, Ceramic | F12: Through Hole | G12: Fast Blow | H12: 5 | I12: 600 | K12: 10000 | L12: 10000 | M12: 10kA | N12: 10 | O12: UL | P12: -55°C ~ 125°C | Q12: 3AB, 3AG, 1/4" x 1-1/4" (Axial) | R12: 0.275" Dia x 1.288" L (6.99mm x 32.72mm) | S12: — | T12: Link | U12: fuses.csv | V12: OK
A13: BK-AHC-V2-5-R | B13: Eaton - Electronics Division | C13: AHC | D13: FUSE CERAMIC 5A 600VAC 3AB 3AG | E13: Cartridge, Ceramic | F13: Through Hole | G13: Fast Blow | H13: 5 | I13: 600 | K13: 10000 | L13: 10000 | M13: 10kA | N13: 10 | O13: UL | P13: -55°C ~ 125°C | Q13: 3AB, 3AG, 1/4" x 1-1/4" (Axial) | R13: 0.275" Dia x 1.288" L (6.99mm x 32.72mm) | S13: — | T13: Link | U13: fuses.csv | V13: OK
A14: TR-AHC-V-5-R | B14: Eaton - Electronics Division | C14: AHC | D14: FUSE CERAMIC 5A 600VAC 3AB 3AG | E14: Cartridge, Ceramic | F14: Through Hole | G14: Fast Blow | H14: 5 | I14: 600 | K14: 10000 | L14: 10000 | M14: 10kA | N14: 10 | O14: UL | P14: -55°C ~ 125°C | Q14: 3AB, 3AG, 1/4" x 1-1/4" (Axial) | R14: 0.275" Dia x 1.288" L (6.99mm x 32.72mm) | S14: — | T14: Link | U14: fuses.csv | V14: OK
A15: 0208006.MXEP | B15: Littelfuse Inc. | C15: 208 | D15: FUSE GLASS 6A 350VAC 2AG | E15: Cartridge, Glass | F15: Through Hole | G15: Fast Blow | H15: 6 | I15: 350 | K15: 100 | L15: 100 | M15: 100A | N15: 22.1 | O15: CE, cURus, PSE | P15: -55°C ~ 125°C | Q15: 2AG, 5mm x 15mm (Axial) | R15: 0.185" Dia x 0.570" L (4.70mm x 14.48mm) | S15: — | T15: Link | U15: fuses.csv | V15: OK
A16: SMG-V6 | B16: Mersen USA Newburyport-MA L.L.C. | C16: SMG | D16: 350V 6A .217X.59 2AG FA-L | E16: Cartridge, Glass | F16: Through Hole | G16: Fast Blow | H16: 6 | I16: 350 | K16: 100 | L16: 100 | M16: 100A | O16: CSA, UR | P16: — | Q16: 2AG, 5mm x 15mm (Axial) | R16: 0.244" Dia x 0.709" L (6.20mm x 18.00mm) | S16: — | T16: Link | U16: fuses.csv | V16: OK
A17: 0ADAP6000-RE | B17: Bel Fuse Inc. | C17: 0ADAP | D17: FUSE CERM 6A 600VAC 600VDC 3AB | E17: Cartridge, Ceramic | F17: Through Hole | G17: Fast Blow | H17: 6 | I17: 600 | J17: 600 | K17: 10000 | L17: 10000 | M17: 10kA | N17: 41.76 | O17: cURus | P17: -55°C ~ 125°C | Q17: 3AB, 3AG, 1/4" x 1-1/4" (Axial) | R17: 0.266" Dia x 1.292" H (6.76mm x 32.82mm) | S17: — | T17: Link | U17: fuses.csv | V17: OK
A18: AHC-V-6-R | B18: Eaton - Electronics Division | C18: AHC | D18: FUSE CERAMIC 6A 600VAC 3AB 3AG | E18: Cartridge, Ceramic | F18: Through Hole | G18: Fast Blow | H18: 6 | I18: 600 | K18: 10000 | L18: 10000 | M18: 10kA | N18: 24 | O18: UL | P18: -55°C ~ 125°C | Q18: 3AB, 3AG, 1/4" x 1-1/4" (Axial) | R18: 0.275" Dia x 1.288" L (6.99mm x 32.72mm) | S18: — | T18: Link | U18: fuses.csv | V18: OK
A19: BK-AHC-V-6-R | B19: Eaton - Electronics Division | C19: AHC | D19: FUSE CERAMIC 6A 600VAC 3AB 3AG | E19: Cartridge, Ceramic | F19: Through Hole | G19: Fast Blow | H19: 6 | I19: 600 | K19: 10000 | L19: 10000 | M19: 10kA | N19: 24 | O19: UL | P19: -55°C ~ 125°C | Q19: 3AB, 3AG, 1/4" x 1-1/4" (Axial) | R19: 0.275" Dia x 1.288" L (6.99mm x 32.72mm) | S19: — | T19: Link | U19: fuses.csv | V19: OK
A20: BK-AHC-V2-6-R | B20: Eaton - Electronics Division | C20: AHC | D20: FUSE CERAMIC 2.6A 600VAC 3AB 3AG | E20: Cartridge, Ceramic | F20: Through Hole | G20: Fast Blow | H20: 6 | I20: 600 | K20: 10000 | L20: 10000 | M20: 10kA | N20: 24 | O20: UL | P20: -55°C ~ 125°C | Q20: 3AB, 3AG, 1/4" x 1-1/4" (Axial) | R20: 0.275" Dia x 1.288" L (6.99mm x 32.72mm) | S20: — | T20: Link | U20: fuses.csv | V20: CHECK
A21: TR-AHC-V-6-R | B21: Eaton - Electronics Division | C21: AHC | D21: FUSE CERAMIC 6A 600VAC 3AB 3AG | E21: Cartridge, Ceramic | F21: Through Hole | G21: Fast Blow | H21: 6 | I21: 600 | K21: 10000 | L21: 10000 | M21: 10kA | N21: 24 | O21: UL | P21: -55°C ~ 125°C | Q21: 3AB, 3AG, 1/4" x 1-1/4" (Axial) | R21: 0.275" Dia x 1.288" L (6.99mm x 32.72mm) | S21: — | T21: Link | U21: fuses.csv | V21: OK
A22: 051406.3MXEP | B22: Littelfuse Inc. | C22: 514 | D22: FUSE CERAMIC 6.3A 500VAC 3AB 3AG | E22: Cartridge, Ceramic | F22: Through Hole | G22: Fast Blow | H22: 6.3 | I22: 500 | K22: 5000 | L22: 5000 | M22: 5kA | N22: 13.5 | O22: CE, cURus | P22: -55°C ~ 125°C | Q22: 3AB, 3AG, 1/4" x 1-1/4" (Axial) | R22: 0.275" Dia x 1.288" L (6.99mm x 32.72mm) | S22: — | T22: Link | U22: fuses.csv | V22: OK
A23: 8020.5076.PT | B23: SCHURTER Inc. | C23: SHF 6.3x32 | D23: FUSE CERAMIC 6.3A 500VAC 3AB 3AG | E23: Cartridge, Ceramic | F23: Through Hole | G23: Fast Blow | H23: 6.3 | I23: 500 | J23: 400 | K23: 1500 | L23: 1500 | M23: 1.5kA | O23: cURus | P23: -40°C ~ 85°C | Q23: 3AB, 3AG, 1/4" x 1-1/4" (Axial) | R23: 0.270" Dia x 1.291" L (6.85mm x 32.80mm) | S23: — | T23: Link | U23: fuses.csv | V23: OK
A24: 0208007.MXEP | B24: Littelfuse Inc. | C24: 208 | D24: FUSE GLASS 7A 350VAC 2AG | E24: Cartridge, Glass | F24: Through Hole | G24: Fast Blow | H24: 7 | I24: 350 | K24: 100 | L24: 100 | M24: 100A | N24: 40 | O24: CE, cURus, PSE | P24: -55°C ~ 125°C | Q24: 2AG, 5mm x 15mm (Axial) | R24: 0.185" Dia x 0.570" L (4.70mm x 14.48mm) | S24: — | T24: Link | U24: fuses.csv | V24: OK
A25: SMG-V7 | B25: Mersen USA Newburyport-MA L.L.C. | C25: SMG | D25: 350V 7A .217X.59 2AG FA-L | E25: Cartridge, Glass | F25: Through Hole | G25: Fast Blow | H25: 7 | I25: 350 | K25: 100 | L25: 100 | M25: 100A | O25: CSA, UR | P25: — | Q25: 2AG, 5mm x 15mm (Axial) | R25: 0.244" Dia x 0.709" L (6.20mm x 18.00mm) | S25: — | T25: Link | U25: fuses.csv | V25: OK
A26: 0208008.MXEP | B26: Littelfuse Inc. | C26: 208 | D26: FUSE GLASS 8A 350VAC 2AG | E26: Cartridge, Glass | F26: Through Hole | G26: Fast Blow | H26: 8 | I26: 350 | K26: 100 | L26: 100 | M26: 100A | N26: 56 | O26: CE, cURus, PSE | P26: -55°C ~ 125°C | Q26: 2AG, 5mm x 15mm (Axial) | R26: 0.185" Dia x 0.570" L (4.70mm x 14.48mm) | S26: — | T26: Link | U26: fuses.csv | V26: OK
A27: 0487008.MXEP | B27: Littelfuse Inc. | C27: 487 | D27: FUSE CERM 8A 420VAC 420VDC 5X20 | E27: Cartridge, Ceramic | F27: Through Hole | G27: Fast Blow | H27: 8 | I27: 420 | J27: 420 | K27: 200 | L27: 300 | M27: 200A AC, 300A DC | N27: 65 | O27: TUV, UR | P27: -55°C ~ 125°C | Q27: 5mm x 20mm (Axial) | R27: 0.217" Dia x 0.846" L (5.50mm x 21.50mm) | S27: — | T27: Link | U27: fuses.csv | V27: OK
A28: BK/S520-V-8-R | B28: Eaton - Electronics Division | C28: S520 | D28: FUSE CERAMIC 8A 420VAC 5X20MM | E28: Cartridge, Ceramic | F28: Through Hole | G28: Fast Blow | H28: 8 | I28: 420 | K28: 200 | L28: 200 | M28: 200A | N28: 104 | O28: TUV, UR | P28: -55°C ~ 125°C | Q28: 5mm x 20mm (Axial) | R28: 0.236" Dia x 0.831" L (6.00mm x 21.10mm) | S28: — | T28: Link | U28: fuses.csv | V28: OK
A29: TR2/S520-V-8-R | B29: Eaton - Electronics Division | C29: S520 | D29: FUSE CERAMIC 8A 420VAC 5X20MM | E29: Cartridge, Ceramic | F29: Through Hole | G29: Fast Blow | H29: 8 | I29: 420 | K29: 1500 | L29: 1500 | M29: 1.5kA | N29: 104 | O29: TUV, UR | P29: -55°C ~ 125°C | Q29: 5mm x 20mm (Axial) | R29: 0.236" Dia x 0.831" L (6.00mm x 21.10mm) | S29: — | T29: Link | U29: fuses.csv | V29: OK
A30: 0514008.MXEP | B30: Littelfuse Inc. | C30: 514 | D30: FUSE CERAMIC 8A 500VAC 3AB 3AG | E30: Cartridge, Ceramic | F30: Through Hole | G30: Fast Blow | H30: 8 | I30: 500 | K30: 5000 | L30: 5000 | M30: 5kA | N30: 28.8 | O30: CE, cURus | P30: -55°C ~ 125°C | Q30: 3AB, 3AG, 1/4" x 1-1/4" (Axial) | R30: 0.275" Dia x 1.288" L (6.99mm x 32.72mm) | S30: — | T30: Link | U30: fuses.csv | V30: OK
A31: 8020.5077.PT | B31: SCHURTER Inc. | C31: SHF 6.3x32 | D31: FUSE CERAMIC 8A 500VAC 3AB 3AG | E31: Cartridge, Ceramic | F31: Through Hole | G31: Fast Blow | H31: 8 | I31: 500 | K31: 1500 | L31: 1500 | M31: 1.5kA | N31: 120 | O31: cURus | P31: -40°C ~ 85°C | Q31: 3AB, 3AG, 1/4" x 1-1/4" (Axial) | R31: 0.270" Dia x 1.291" L (6.85mm x 32.80mm) | S31: — | T31: Link | U31: fuses.csv | V31: OK
A32: 0ADAP8000-RE | B32: Bel Fuse Inc. | C32: 0ADAP | D32: FUSE CERM 8A 600VAC 600VDC 3AB | E32: Cartridge, Ceramic | F32: Through Hole | G32: Fast Blow | H32: 8 | I32: 600 | J32: 600 | K32: 10000 | L32: 10000 | M32: 10kA | N32: 76.8 | O32: cURus | P32: -55°C ~ 125°C | Q32: 3AB, 3AG, 1/4" x 1-1/4" (Axial) | R32: 0.266" Dia x 1.292" H (6.76mm x 32.82mm) | S32: — | T32: Link | U32: fuses.csv | V32: OK
A33: AHC-V-8-R | B33: Eaton - Electronics Division | C33: AHC | D33: FUSE CERAMIC 8A 600VAC 3AB 3AG | E33: Cartridge, Ceramic | F33: Through Hole | G33: Fast Blow | H33: 8 | I33: 600 | K33: 10000 | L33: 10000 | M33: 10kA | N33: 35 | O33: UL | P33: -55°C ~ 125°C | Q33: 3AB, 3AG, 1/4" x 1-1/4" (Axial) | R33: 0.275" Dia x 1.288" L (6.99mm x 32.72mm) | S33: — | T33: Link | U33: fuses.csv | V33: OK
A34: BK-AHC-V-8-R | B34: Eaton - Electronics Division | C34: AHC | D34: FUSE CERAMIC 8A 600VAC 3AB 3AG | E34: Cartridge, Ceramic | F34: Through Hole | G34: Fast Blow | H34: 8 | I34: 600 | K34: 10000 | L34: 10000 | M34: 10kA | N34: 35 | O34: UL | P34: -55°C ~ 125°C | Q34: 3AB, 3AG, 1/4" x 1-1/4" (Axial) | R34: 0.275" Dia x 1.288" L (6.99mm x 32.72mm) | S34: — | T34: Link | U34: fuses.csv | V34: OK
A35: BK-AHC-V2-8-R | B35: Eaton - Electronics Division | C35: AHC | D35: FUSE CERAMIC 8A 600VAC 3AB 3AG | E35: Cartridge, Ceramic | F35: Through Hole | G35: Fast Blow | H35: 8 | I35: 600 | K35: 10000 | L35: 10000 | M35: 10kA | N35: 35 | O35: UL | P35: -55°C ~ 125°C | Q35: 3AB, 3AG, 1/4" x 1-1/4" (Axial) | R35: 0.275" Dia x 1.288" L (6.99mm x 32.72mm) | S35: — | T35: Link | U35: fuses.csv | V35: OK
A36: SCV8 | B36: Eaton - Bussmann Electrical Division | C36: SCV | D36: FUSE CERAMIC | E36: Cartridge, Ceramic | F36: Through Hole | G36: Fast Blow | H36: 8 | I36: 600 | J36: 170 | K36: 100000 | L36: 10000 | M36: 100kA AC, 10kA DC | O36: CE | P36: — | Q36: Radial Bend Cylinder | R36: 0.409" Dia x 1.311" L (10.40mm x 33.30mm) | S36: — | U36: fuses.csv | V36: OK
A37: TR-AHC-V-8-R | B37: Eaton - Electronics Division | C37: AHC | D37: FUSE CERAMIC 8A 600VAC 3AB 3AG | E37: Cartridge, Ceramic | F37: Through Hole | G37: Fast Blow | H37: 8 | I37: 600 | K37: 10000 | L37: 10000 | M37: 10kA | N37: 35 | O37: UL | P37: -55°C ~ 125°C | Q37: 3AB, 3AG, 1/4" x 1-1/4" (Axial) | R37: 0.275" Dia x 1.288" L (6.99mm x 32.72mm) | S37: — | T37: Link | U37: fuses.csv | V37: OK
A38: 0208010.MXEP | B38: Littelfuse Inc. | C38: 208 | D38: FUSE GLASS 10A 350VAC 2AG | E38: Cartridge, Glass | F38: Through Hole | G38: Fast Blow | H38: 10 | I38: 350 | K38: 100 | L38: 100 | M38: 100A | N38: 116 | O38: CE, cURus, PSE | P38: -55°C ~ 125°C | Q38: 2AG, 5mm x 15mm (Axial) | R38: 0.185" Dia x 0.570" L (4.70mm x 14.48mm) | S38: — | T38: Link | U38: fuses.csv | V38: OK
A39: 0487010.MXEP | B39: Littelfuse Inc. | C39: 487 | D39: FUSE CERM 10A 420VAC 420VDC 5X20 | E39: Cartridge, Ceramic | F39: Through Hole | G39: Fast Blow | H39: 10 | I39: 420 | J39: 420 | K39: 200 | L39: 300 | M39: 200A AC, 300A DC | N39: 130 | O39: TUV, UR | P39: -55°C ~ 125°C | Q39: 5mm x 20mm (Axial) | R39: 0.217" Dia x 0.846" L (5.50mm x 21.50mm) | S39: — | T39: Link | U39: fuses.csv | V39: OK
A40: BK/S520-V-10-R | B40: Eaton - Electronics Division | C40: S520 | D40: FUSE CERAMIC 10A 420VAC 5X20MM | E40: Cartridge, Ceramic | F40: Through Hole | G40: Fast Blow | H40: 10 | I40: 420 | K40: 200 | L40: 200 | M40: 200A | N40: 155 | O40: TUV, UR | P40: -55°C ~ 125°C | Q40: 5mm x 20mm (Axial) | R40: 0.236" Dia x 0.831" L (6.00mm x 21.10mm) | S40: — | T40: Link | U40: fuses.csv | V40: OK
A41: TR2/S520-V-10-R | B41: Eaton - Electronics Division | C41: S520 | D41: FUSE CERAMIC 10A 420VAC 5X20MM | E41: Cartridge, Ceramic | F41: Through Hole | G41: Fast Blow | H41: 10 | I41: 420 | K41: 1500 | L41: 1500 | M41: 1.5kA | N41: 155 | O41: TUV, UR | P41: -55°C ~ 125°C | Q41: 5mm x 20mm (Axial) | R41: 0.236" Dia x 0.831" L (6.00mm x 21.10mm) | S41: — | T41: Link | U41: fuses.csv | V41: OK
...

Sheet Summary
A1: Fuse Database — Summary
A2: All figures are live COUNTIF formulas against the Fuse Database sheet.
A4: Overview
A5: Total parts | B5: =COUNTA('Fuse Database'!A5:A119) -> 115
A6: Parts flagged for review (QC = CHECK) | B6: =COUNTIF('Fuse Database'!V5:V119,"CHECK") -> 3
A7: Distinct manufacturers | B7: 8 | C7: from source data
A9: Parts by Manufacturer | D9: Parts by Fuse Type | G9: Parts by Current Rating (A)
A10: Manufacturer | B10: Count | D10: Fuse Type | E10: Count | G10: Rating (A) | H10: Count
A11: Littelfuse Inc. | B11: =COUNTIF('Fuse Database'!B5:B119,A11) -> 30 | D11: Cartridge, Ceramic | E11: =COUNTIF('Fuse Database'!E5:E119,D11) -> 106 | G11: 5 | H11: =COUNTIF('Fuse Database'!H5:H119,G11) -> 10
A12: Eaton - Electronics Division | B12: =COUNTIF('Fuse Database'!B5:B119,A12) -> 55 | D12: Cartridge, Glass | E12: =COUNTIF('Fuse Database'!E5:E119,D12) -> 9 | G12: 6 | H12: =COUNTIF('Fuse Database'!H5:H119,G12) -> 7
A13: Bel Fuse Inc. | B13: =COUNTIF('Fuse Database'!B5:B119,A13) -> 12 | G13: 6.3 | H13: =COUNTIF('Fuse Database'!H5:H119,G13) -> 2
A14: Bourns Inc. | B14: =COUNTIF('Fuse Database'!B5:B119,A14) -> 9 | G14: 7 | H14: =COUNTIF('Fuse Database'!H5:H119,G14) -> 2
A15: Mersen USA Newburyport-MA L.L.C. | B15: =COUNTIF('Fuse Database'!B5:B119,A15) -> 3 | G15: 8 | H15: =COUNTIF('Fuse Database'!H5:H119,G15) -> 12
A16: SCHURTER Inc. | B16: =COUNTIF('Fuse Database'!B5:B119,A16) -> 3 | G16: 10 | H16: =COUNTIF('Fuse Database'!H5:H119,G16) -> 14
A17: Conquer | B17: =COUNTIF('Fuse Database'!B5:B119,A17) -> 2 | G17: 12 | H17: =COUNTIF('Fuse Database'!H5:H119,G17) -> 5
A18: Eaton - Bussmann Electrical Division | B18: =COUNTIF('Fuse Database'!B5:B119,A18) -> 1 | G18: 12.5 | H18: =COUNTIF('Fuse Database'!H5:H119,G18) -> 5
A19: Total | B19: =SUM(B11:B18) -> 115 | G19: 15 | H19: =COUNTIF('Fuse Database'!H5:H119,G19) -> 10
G20: 16 | H20: =COUNTIF('Fuse Database'!H5:H119,G20) -> 6
G21: 18 | H21: =COUNTIF('Fuse Database'!H5:H119,G21) -> 4
G22: 20 | H22: =COUNTIF('Fuse Database'!H5:H119,G22) -> 13
G23: 25 | H23: =COUNTIF('Fuse Database'!H5:H119,G23) -> 7
G24: 30 | H24: =COUNTIF('Fuse Database'!H5:H119,G24) -> 13
G25: 35 | H25: =COUNTIF('Fuse Database'!H5:H119,G25) -> 1
G26: 40 | H26: =COUNTIF('Fuse Database'!H5:H119,G26) -> 3
G27: 50 | H27: =COUNTIF('Fuse Database'!H5:H119,G27) -> 1
G28: Total | H28: =SUM(H11:H27) -> 115

Sheet Data Quality
A1: Data Quality Notes
A3: Cleaning applied to this database (vs. the original source):
A4: • The source "Current Rating (Amps)" column was corrupted by spreadsheet time-parsing (e.g. "5:00 AM" instead of "5 A"). The numeric current rating was recovered and is shown in the "Current Rating (A)" column.
A5: • ~30 helper/parse/scratch columns from the source were removed; numeric values were retained as clean typed columns.
A6: • Voltage, breaking capacity and melting I²t were normalised to numeric columns; empty "—" means the source listed no value.
A7: • No duplicate Mfr Part # values were present in the source.
A9: Parts flagged CHECK — rating field disagrees with description
A10: Mfr Part # | B10: Rating field (A) | C10: Description (A) | D10: Difference | E10: Description text
A11: BK-AHC-V2-6-R | B11: 6 | C11: 2.6 | D11: field ≠ description | E11: FUSE CERAMIC 2.6A 600VAC 3AB 3AG
A12: BK-AHCA-V-1-5-R | B12: 15 | C12: 1.5 | D12: field ≠ description | E12: AHCA 600V FUSE, 1.5A
A13: BK-AHCA-V-2-5-R | B13: 25 | C13: 2.5 | D13: field ≠ description | E13: AHCA 600V FUSE, 2.5A
A15: Recommendation: verify these three parts against their datasheets; the description value is likely correct (decimal ratings mis-read as integers).
